Workbook

Sheet refs
A1: 1RM
A2: Exercice | B2: Load
A3: Squat | B3: 120
A4: Bench | B4: 95
A5: Deadlift | B5: 225
A6: Total | B6: =SUM(B3:B5) -> 440
A8: Renfo
A9: Exercice | B9: Reps | C9: Load
A10: Pull-ups | B10: 5 | C10: 0
A11: Dips | B11: 8 | C11: 0
A12: Lateral raises | B12: 15 | C12: 14
A13: Strict curl | B13: 15 | C13: 14
A14: Dumbbel rowing | B14: 8 | C14: 46
A15: Hammer curl | B15: 8 | C15: 26

Sheet week 1
A1: =refs!A10 -> Pull-ups
A2: Exercice | B2: Reps | C2: RPE | D2: Percentage | E2: Load | F2: e1RM | G2: Part
A3: 2CT Paused Bench | B3: 3 | C3: 6 | D3: 82 | E3: =D3/100*refs!B4 -> 77.9 | F3: =IF(OR(C3="?",E3<=0), "?", ROUND(E3*(1+(B3+(10-C3))/30),1)) -> 96.1
A4: 2CT Paused Bench | B4: 3 | C4: 8 | D4: 87 | E4: =D4/100*refs!B4 -> 82.65 | F4: =IF(OR(C4="?",E4<=0), "?", ROUND(E4*(1+(B4+(10-C4))/30),1)) -> 96.4
A5: 2CT Paused Bench | B5: 3 | C5: 8 | D5: 87 | E5: =D5/100*refs!B4 -> 82.65 | F5: =IF(OR(C5="?",E5<=0), "?", ROUND(E5*(1+(B5+(10-C5))/30),1)) -> 96.4
A6: Larsen 2CT Paused | B6: 3 | C6: ? | D6: 82 | E6: =D6/100*refs!B4 -> 77.9 | F6: =IF(OR(C6="?",E6<=0), "?", ROUND(E6*(1+(B6+(10-C6))/30),1)) -> ?
A7: Larsen 2CT Paused | B7: 3 | C7: ? | D7: 82 | E7: =D7/100*refs!B4 -> 77.9 | F7: =IF(OR(C7="?",E7<=0), "?", ROUND(E7*(1+(B7+(10-C7))/30),1)) -> ?
A8: Deadlift | B8: 3 | C8: 5 | D8: 79 | E8: =D8/100*refs!B5 -> 177.75 | F8: =IF(OR(C8="?",E8<=0), "?", ROUND(E8*(1+(B8+(10-C8))/30),1)) -> 225.2
A9: Deadlift | B9: 3 | C9: 7 | D9: 84 | E9: =D9/100*refs!B5 -> 189 | F9: =IF(OR(C9="?",E9<=0), "?", ROUND(E9*(1+(B9+(10-C9))/30),1)) -> 226.8
A10: Deadlift | B10: 3 | C10: 5 | D10: 79 | E10: =D10/100*refs!B5 -> 177.75 | F10: =IF(OR(C10="?",E10<=0), "?", ROUND(E10*(1+(B10+(10-C10))/30),1)) -> 225.2
A11: Paused deadlift | B11: 3 | C11: 6 | D11: 75 | E11: =D11/100*refs!B5 -> 168.75 | F11: =IF(OR(C11="?",E11<=0), "?", ROUND(E11*(1+(B11+(10-C11))/30),1)) -> 208.1
A12: Paused deadlift | B12: 3 | C12: 8 | D12: 81 | E12: =D12/100*refs!B5 -> 182.25 | F12: =IF(OR(C12="?",E12<=0), "?", ROUND(E12*(1+(B12+(10-C12))/30),1)) -> 212.6
A13: =refs!A10 -> Pull-ups | B13: =refs!B10 -> 5 | C13: 8 | E13: =refs!C10 -> 0 | F13: =IF(OR(C13="?",E13<=0), "?", ROUND(E13*(1+(B13+(10-C13))/30),1)) -> ?
A14: =refs!A10 -> Pull-ups | B14: =refs!B10 -> 5 | C14: 8 | E14: =refs!C10 -> 0 | F14: =IF(OR(C14="?",E14<=0), "?", ROUND(E14*(1+(B14+(10-C14))/30),1)) -> ?
A15: =refs!A10 -> Pull-ups | B15: =refs!B10 -> 5 | C15: 8 | E15: =refs!C10 -> 0 | F15: =IF(OR(C15="?",E15<=0), "?", ROUND(E15*(1+(B15+(10-C15))/30),1)) -> ?
A16: =refs!A10 -> Pull-ups | B16: =refs!B10 -> 5 | C16: 8 | E16: =refs!C10 -> 0 | F16: =IF(OR(C16="?",E16<=0), "?", ROUND(E16*(1+(B16+(10-C16))/30),1)) -> ?
A17: =refs!A11 -> Dips | B17: =refs!B11 -> 8 | C17: 8 | E17: =refs!C11 -> 0 | F17: =IF(OR(C17="?",E17<=0), "?", ROUND(E17*(1+(B17+(10-C17))/30),1)) -> ?
A18: =refs!A11 -> Dips | B18: =refs!B11 -> 8 | C18: 8 | E18: =refs!C11 -> 0 | F18: =IF(OR(C18="?",E18<=0), "?", ROUND(E18*(1+(B18+(10-C18))/30),1)) -> ?
A19: =refs!A11 -> Dips | B19: =refs!B11 -> 8 | C19: 8 | E19: =refs!C11 -> 0 | F19: =IF(OR(C19="?",E19<=0), "?", ROUND(E19*(1+(B19+(10-C19))/30),1)) -> ?
A20: =refs!A11 -> Dips | B20: =refs!B11 -> 8 | C20: 8 | E20: =refs!C11 -> 0 | F20: =IF(OR(C20="?",E20<=0), "?", ROUND(E20*(1+(B20+(10-C20))/30),1)) -> ?
A21: =refs!A12 -> Lateral raises | B21: =refs!B12 -> 15 | C21: 8 | E21: =refs!C12 -> 14 | F21: =IF(OR(C21="?",E21<=0), "?", ROUND(E21*(1+(B21+(10-C21))/30),1)) -> 21.9 | G21: 2
A22: =refs!A12 -> Lateral raises | B22: =refs!B12 -> 15 | C22: 8 | E22: =refs!C12 -> 14 | F22: =IF(OR(C22="?",E22<=0), "?", ROUND(E22*(1+(B22+(10-C22))/30),1)) -> 21.9
A23: =refs!A12 -> Lateral raises | B23: =refs!B12 -> 15 | C23: 8 | E23: =refs!C12 -> 14 | F23: =IF(OR(C23="?",E23<=0), "?", ROUND(E23*(1+(B23+(10-C23))/30),1)) -> 21.9
A24: =refs!A12 -> Lateral raises | B24: =refs!B12 -> 15 | C24: 8 | E24: =refs!C12 -> 14 | F24: =IF(OR(C24="?",E24<=0), "?", ROUND(E24*(1+(B24+(10-C24))/30),1)) -> 21.9
A25: =refs!A13 -> Strict curl | B25: =refs!B13 -> 15 | C25: 8 | E25: =refs!C13 -> 14 | F25: =IF(OR(C25="?",E25<=0), "?", ROUND(E25*(1+(B25+(10-C25))/30),1)) -> 21.9
A26: =refs!A13 -> Strict curl | B26: =refs!B13 -> 15 | C26: 8 | E26: =refs!C13 -> 14 | F26: =IF(OR(C26="?",E26<=0), "?", ROUND(E26*(1+(B26+(10-C26))/30),1)) -> 21.9
A27: =refs!A13 -> Strict curl | B27: =refs!B13 -> 15 | C27: 8 | E27: =refs!C13 -> 14 | F27: =IF(OR(C27="?",E27<=0), "?", ROUND(E27*(1+(B27+(10-C27))/30),1)) -> 21.9
A28: =refs!A13 -> Strict curl | B28: =refs!B13 -> 15 | C28: 8 | E28: =refs!C13 -> 14 | F28: =IF(OR(C28="?",E28<=0), "?", ROUND(E28*(1+(B28+(10-C28))/30),1)) -> 21.9
A30: WEEK 1 DAY 2
A31: Exercice | B31: Reps | C31: RPE | D31: Percentage | E31: Load | F31: e1RM | G31: Part
A32: Squat | B32: 3 | C32: 5 | D32: 79 | E32: =D32/100*refs!B3 -> 94.8 | F32: =IF(OR(C32="?",E32<=0), "?", ROUND(E32*(1+(B32+(10-C32))/30),1)) -> 120.1 | G32: 1
A33: Squat | B33: 3 | C33: 7 | D33: 84 | E33: =D33/100*refs!B3 -> 100.8 | F33: =IF(OR(C33="?",E33<=0), "?", ROUND(E33*(1+(B33+(10-C33))/30),1)) -> 121
A34: Squat | B34: 3 | C34: 6 | D34: 82 | E34: =D34/100*refs!B3 -> 98.4 | F34: =IF(OR(C34="?",E34<=0), "?", ROUND(E34*(1+(B34+(10-C34))/30),1)) -> 121.4
A35: Tempo squat 3:1:3 | B35: 5 | C35: 7 | D35: 77 | E35: =D35/100*refs!B3 -> 92.4 | F35: =IF(OR(C35="?",E35<=0), "?", ROUND(E35*(1+(B35+(10-C35))/30),1)) -> 117
A36: Tempo squat 3:1:3 | B36: 5 | C36: 7 | D36: 77 | E36: =D36/100*refs!B3 -> 92.4 | F36: =IF(OR(C36="?",E36<=0), "?", ROUND(E36*(1+(B36+(10-C36))/30),1)) -> 117
A37: Tempo squat 3:1:3 | B37: 5 | C37: 7 | D37: 77 | E37: =D37/100*refs!B3 -> 92.4 | F37: =IF(OR(C37="?",E37<=0), "?", ROUND(E37*(1+(B37+(10-C37))/30),1)) -> 117
A38: Bench | B38: 7 | C38: 6 | D38: 71 | E38: =D38/100*refs!B4 -> 67.45 | F38: =IF(OR(C38="?",E38<=0), "?", ROUND(E38*(1+(B38+(10-C38))/30),1)) -> 92.2
A39: Bench | B39: 7 | C39: 8 | D39: 77 | E39: =D39/100*refs!B4 -> 73.15 | F39: =IF(OR(C39="?",E39<=0), "?", ROUND(E39*(1+(B39+(10-C39))/30),1)) -> 95.1
A40: Bench | B40: 7 | C40: ? | D40: 71 | E40: =D40/100*refs!B4 -> 67.45 | F40: =IF(OR(C40="?",E40<=0), "?", ROUND(E40*(1+(B40+(10-C40))/30),1)) -> ?
A41: Bench | B41: 7 | C41: ? | D41: 66 | E41: =D41/100*refs!B4 -> 62.7 | F41: =IF(OR(C41="?",E41<=0), "?", ROUND(E41*(1+(B41+(10-C41))/30),1)) -> ?
...

Sheet week 2
A1: WEEK 2 DAY 1
A2: Exercice | B2: Reps | C2: RPE | D2: Percentage | E2: Load | F2: e1RM | G2: Part
A3: 2CT Paused Bench | B3: 3 | C3: 6 | D3: 82 | E3: =D3/100*refs!B4 -> 77.9 | F3: =IF(OR(C3="?",E3<=0), "?", ROUND(E3*(1+(B3+(10-C3))/30),1)) -> 96.1
A4: 2CT Paused Bench | B4: 3 | C4: 8 | D4: 87 | E4: =D4/100*refs!B4 -> 82.65 | F4: =IF(OR(C4="?",E4<=0), "?", ROUND(E4*(1+(B4+(10-C4))/30),1)) -> 96.4
A5: 2CT Paused Bench | B5: 3 | C5: 8 | D5: 87 | E5: =D5/100*refs!B4 -> 82.65 | F5: =IF(OR(C5="?",E5<=0), "?", ROUND(E5*(1+(B5+(10-C5))/30),1)) -> 96.4
A6: 2CT Paused Bench | B6: 3 | C6: ? | D6: 82 | E6: =D6/100*refs!B4 -> 77.9 | F6: =IF(OR(C6="?",E6<=0), "?", ROUND(E6*(1+(B6+(10-C6))/30),1)) -> ?
A7: 2CT Paused Bench | B7: 3 | C7: ? | D7: 82 | E7: =D7/100*refs!B4 -> 77.9 | F7: =IF(OR(C7="?",E7<=0), "?", ROUND(E7*(1+(B7+(10-C7))/30),1)) -> ?
A8: Deadlift | B8: 3 | C8: 6 | D8: 82 | E8: =D8/100*refs!B5 -> 184.5 | F8: =IF(OR(C8="?",E8<=0), "?", ROUND(E8*(1+(B8+(10-C8))/30),1)) -> 227.6
A9: Deadlift | B9: 3 | C9: 8 | D9: 87 | E9: =D9/100*refs!B5 -> 195.75 | F9: =IF(OR(C9="?",E9<=0), "?", ROUND(E9*(1+(B9+(10-C9))/30),1)) -> 228.4
A10: Deadlift | B10: 3 | C10: 6 | D10: 82 | E10: =D10/100*refs!B5 -> 184.5 | F10: =IF(OR(C10="?",E10<=0), "?", ROUND(E10*(1+(B10+(10-C10))/30),1)) -> 227.6
A11: Paused deadlift | B11: 3 | C11: 6 | D11: 75 | E11: =D11/100*refs!B5 -> 168.75 | F11: =IF(OR(C11="?",E11<=0), "?", ROUND(E11*(1+(B11+(10-C11))/30),1)) -> 208.1
A12: Paused deadlift | B12: 3 | C12: 8 | D12: 81 | E12: =D12/100*refs!B5 -> 182.25 | F12: =IF(OR(C12="?",E12<=0), "?", ROUND(E12*(1+(B12+(10-C12))/30),1)) -> 212.6
A13: Paused deadlift | B13: 3 | C13: 6 | D13: 75 | E13: =D13/100*refs!B5 -> 168.75 | F13: =IF(OR(C13="?",E13<=0), "?", ROUND(E13*(1+(B13+(10-C13))/30),1)) -> 208.1
A14: =refs!A10 -> Pull-ups | B14: =refs!B10 -> 5 | C14: 8 | E14: =refs!C10 -> 0 | F14: =IF(OR(C14="?",E14<=0), "?", ROUND(E14*(1+(B14+(10-C14))/30),1)) -> ?
A15: =refs!A10 -> Pull-ups | B15: =refs!B10 -> 5 | C15: 8 | E15: =refs!C10 -> 0 | F15: =IF(OR(C15="?",E15<=0), "?", ROUND(E15*(1+(B15+(10-C15))/30),1)) -> ?
A16: =refs!A10 -> Pull-ups | B16: =refs!B10 -> 5 | C16: 8 | E16: =refs!C10 -> 0 | F16: =IF(OR(C16="?",E16<=0), "?", ROUND(E16*(1+(B16+(10-C16))/30),1)) -> ?
A17: =refs!A10 -> Pull-ups | B17: =refs!B10 -> 5 | C17: 8 | E17: =refs!C10 -> 0 | F17: =IF(OR(C17="?",E17<=0), "?", ROUND(E17*(1+(B17+(10-C17))/30),1)) -> ?
A18: =refs!A11 -> Dips | B18: =refs!B11 -> 8 | C18: 8 | E18: =refs!C11 -> 0 | F18: =IF(OR(C18="?",E18<=0), "?", ROUND(E18*(1+(B18+(10-C18))/30),1)) -> ?
A19: =refs!A11 -> Dips | B19: =refs!B11 -> 8 | C19: 8 | E19: =refs!C11 -> 0 | F19: =IF(OR(C19="?",E19<=0), "?", ROUND(E19*(1+(B19+(10-C19))/30),1)) -> ?
A20: =refs!A11 -> Dips | B20: =refs!B11 -> 8 | C20: 8 | E20: =refs!C11 -> 0 | F20: =IF(OR(C20="?",E20<=0), "?", ROUND(E20*(1+(B20+(10-C20))/30),1)) -> ?
A21: =refs!A11 -> Dips | B21: =refs!B11 -> 8 | C21: 8 | E21: =refs!C11 -> 0 | F21: =IF(OR(C21="?",E21<=0), "?", ROUND(E21*(1+(B21+(10-C21))/30),1)) -> ?
A22: =refs!A12 -> Lateral raises | B22: =refs!B12 -> 15 | C22: 8 | E22: =refs!C12 -> 14 | F22: =IF(OR(C22="?",E22<=0), "?", ROUND(E22*(1+(B22+(10-C22))/30),1)) -> 21.9 | G22: 2
A23: =refs!A12 -> Lateral raises | B23: =refs!B12 -> 15 | C23: 8 | E23: =refs!C12 -> 14 | F23: =IF(OR(C23="?",E23<=0), "?", ROUND(E23*(1+(B23+(10-C23))/30),1)) -> 21.9
A24: =refs!A12 -> Lateral raises | B24: =refs!B12 -> 15 | C24: 8 | E24: =refs!C12 -> 14 | F24: =IF(OR(C24="?",E24<=0), "?", ROUND(E24*(1+(B24+(10-C24))/30),1)) -> 21.9
A25: =refs!A12 -> Lateral raises | B25: =refs!B12 -> 15 | C25: 8 | E25: =refs!C12 -> 14 | F25: =IF(OR(C25="?",E25<=0), "?", ROUND(E25*(1+(B25+(10-C25))/30),1)) -> 21.9
A26: =refs!A13 -> Strict curl | B26: =refs!B13 -> 15 | C26: 8 | E26: =refs!C13 -> 14 | F26: =IF(OR(C26="?",E26<=0), "?", ROUND(E26*(1+(B26+(10-C26))/30),1)) -> 21.9
A27: =refs!A13 -> Strict curl | B27: =refs!B13 -> 15 | C27: 8 | E27: =refs!C13 -> 14 | F27: =IF(OR(C27="?",E27<=0), "?", ROUND(E27*(1+(B27+(10-C27))/30),1)) -> 21.9
A28: =refs!A13 -> Strict curl | B28: =refs!B13 -> 15 | C28: 8 | E28: =refs!C13 -> 14 | F28: =IF(OR(C28="?",E28<=0), "?", ROUND(E28*(1+(B28+(10-C28))/30),1)) -> 21.9
A29: =refs!A13 -> Strict curl | B29: =refs!B13 -> 15 | C29: 8 | E29: =refs!C13 -> 14 | F29: =IF(OR(C29="?",E29<=0), "?", ROUND(E29*(1+(B29+(10-C29))/30),1)) -> 21.9
A31: WEEK 2 DAY 2
A32: Exercice | B32: Reps | C32: RPE | D32: Percentage | E32: Load | F32: e1RM | G32: Part
A33: Squat | B33: 3 | C33: 6 | D33: 82 | E33: =D33/100*refs!B3 -> 98.4 | F33: =IF(OR(C33="?",E33<=0), "?", ROUND(E33*(1+(B33+(10-C33))/30),1)) -> 121.4 | G33: 1
A34: Squat | B34: 3 | C34: 8 | D34: 87 | E34: =D34/100*refs!B3 -> 104.4 | F34: =IF(OR(C34="?",E34<=0), "?", ROUND(E34*(1+(B34+(10-C34))/30),1)) -> 121.8
A35: Squat | B35: 3 | C35: 7 | D35: 84 | E35: =D35/100*refs!B3 -> 100.8 | F35: =IF(OR(C35="?",E35<=0), "?", ROUND(E35*(1+(B35+(10-C35))/30),1)) -> 121
A36: Squat | B36: 3 | C36: 7 | D36: 84 | E36: =D36/100*refs!B3 -> 100.8 | F36: =IF(OR(C36="?",E36<=0), "?", ROUND(E36*(1+(B36+(10-C36))/30),1)) -> 121
A37: Tempo squat 3:1:3 | B37: 5 | C37: 7 | D37: 77 | E37: =D37/100*refs!B3 -> 92.4 | F37: =IF(OR(C37="?",E37<=0), "?", ROUND(E37*(1+(B37+(10-C37))/30),1)) -> 117
A38: Tempo squat 3:1:3 | B38: 5 | C38: 7 | D38: 77 | E38: =D38/100*refs!B3 -> 92.4 | F38: =IF(OR(C38="?",E38<=0), "?", ROUND(E38*(1+(B38+(10-C38))/30),1)) -> 117
A39: Tempo squat 3:1:3 | B39: 5 | C39: 7 | D39: 77 | E39: =D39/100*refs!B3 -> 92.4 | F39: =IF(OR(C39="?",E39<=0), "?", ROUND(E39*(1+(B39+(10-C39))/30),1)) -> 117
A40: Bench | B40: 7 | C40: 6 | D40: 71 | E40: =D40/100*refs!B4 -> 67.45 | F40: =IF(OR(C40="?",E40<=0), "?", ROUND(E40*(1+(B40+(10-C40))/30),1)) -> 92.2
A41: Bench | B41: 7 | C41: 8 | D41: 77 | E41: =D41/100*refs!B4 -> 73.15 | F41: =IF(OR(C41="?",E41<=0), "?", ROUND(E41*(1+(B41+(10-C41))/30),1)) -> 95.1
...

Sheet week 3
A1: WEEK 3 DAY 1
A2: Exercice | B2: Reps | C2: RPE | D2: Percentage | E2: Load | F2: e1RM | G2: Part
A3: 2CT Paused Bench | B3: 3 | C3: 5 | D3: 79 | E3: =D3/100*refs!B4 -> 75.05 | F3: =IF(OR(C3="?",E3<=0), "?", ROUND(E3*(1+(B3+(10-C3))/30),1)) -> 95.1
A4: 2CT Paused Bench | B4: 3 | C4: 7 | D4: 84 | E4: =D4/100*refs!B4 -> 79.8 | F4: =IF(OR(C4="?",E4<=0), "?", ROUND(E4*(1+(B4+(10-C4))/30),1)) -> 95.8
A5: 2CT Paused Bench | B5: 3 | C5: 9 | D5: 90 | E5: =D5/100*refs!B4 -> 85.5 | F5: =IF(OR(C5="?",E5<=0), "?", ROUND(E5*(1+(B5+(10-C5))/30),1)) -> 96.9
A6: 2CT Paused Bench | B6: 3 | C6: ? | D6: 82 | E6: =D6/100*refs!B4 -> 77.9 | F6: =IF(OR(C6="?",E6<=0), "?", ROUND(E6*(1+(B6+(10-C6))/30),1)) -> ?
A7: 2CT Paused Bench | B7: 3 | C7: ? | D7: 78 | E7: =D7/100*refs!B4 -> 74.1 | F7: =IF(OR(C7="?",E7<=0), "?", ROUND(E7*(1+(B7+(10-C7))/30),1)) -> ?
A8: Deadlift | B8: 3 | C8: 5 | D8: 79 | E8: =D8/100*refs!B5 -> 177.75 | F8: =IF(OR(C8="?",E8<=0), "?", ROUND(E8*(1+(B8+(10-C8))/30),1)) -> 225.2
A9: Deadlift | B9: 3 | C9: 7 | D9: 85 | E9: =D9/100*refs!B5 -> 191.25 | F9: =IF(OR(C9="?",E9<=0), "?", ROUND(E9*(1+(B9+(10-C9))/30),1)) -> 229.5
A10: Deadlift | B10: 3 | C10: 9 | D10: 90 | E10: =D10/100*refs!B5 -> 202.5 | F10: =IF(OR(C10="?",E10<=0), "?", ROUND(E10*(1+(B10+(10-C10))/30),1)) -> 229.5
A11: Paused deadlift | B11: 3 | C11: 6 | D11: 75 | E11: =D11/100*refs!B5 -> 168.75 | F11: =IF(OR(C11="?",E11<=0), "?", ROUND(E11*(1+(B11+(10-C11))/30),1)) -> 208.1
A12: Paused deadlift | B12: 3 | C12: 8 | D12: 81 | E12: =D12/100*refs!B5 -> 182.25 | F12: =IF(OR(C12="?",E12<=0), "?", ROUND(E12*(1+(B12+(10-C12))/30),1)) -> 212.6
A13: Paused deadlift | B13: 3 | C13: 6 | D13: 75 | E13: =D13/100*refs!B5 -> 168.75 | F13: =IF(OR(C13="?",E13<=0), "?", ROUND(E13*(1+(B13+(10-C13))/30),1)) -> 208.1
A14: =refs!A10 -> Pull-ups | B14: =refs!B10 -> 5 | C14: 8 | E14: =refs!C10 -> 0 | F14: =IF(OR(C14="?",E14<=0), "?", ROUND(E14*(1+(B14+(10-C14))/30),1)) -> ?
A15: =refs!A10 -> Pull-ups | B15: =refs!B10 -> 5 | C15: 8 | E15: =refs!C10 -> 0 | F15: =IF(OR(C15="?",E15<=0), "?", ROUND(E15*(1+(B15+(10-C15))/30),1)) -> ?
A16: =refs!A10 -> Pull-ups | B16: =refs!B10 -> 5 | C16: 8 | E16: =refs!C10 -> 0 | F16: =IF(OR(C16="?",E16<=0), "?", ROUND(E16*(1+(B16+(10-C16))/30),1)) -> ?
A17: =refs!A10 -> Pull-ups | B17: =refs!B10 -> 5 | C17: 8 | E17: =refs!C10 -> 0 | F17: =IF(OR(C17="?",E17<=0), "?", ROUND(E17*(1+(B17+(10-C17))/30),1)) -> ?
A18: =refs!A11 -> Dips | B18: =refs!B11 -> 8 | C18: 8 | E18: =refs!C11 -> 0 | F18: =IF(OR(C18="?",E18<=0), "?", ROUND(E18*(1+(B18+(10-C18))/30),1)) -> ?
A19: =refs!A11 -> Dips | B19: =refs!B11 -> 8 | C19: 8 | E19: =refs!C11 -> 0 | F19: =IF(OR(C19="?",E19<=0), "?", ROUND(E19*(1+(B19+(10-C19))/30),1)) -> ?
A20: =refs!A11 -> Dips | B20: =refs!B11 -> 8 | C20: 8 | E20: =refs!C11 -> 0 | F20: =IF(OR(C20="?",E20<=0), "?", ROUND(E20*(1+(B20+(10-C20))/30),1)) -> ?
A21: =refs!A11 -> Dips | B21: =refs!B11 -> 8 | C21: 8 | E21: =refs!C11 -> 0 | F21: =IF(OR(C21="?",E21<=0), "?", ROUND(E21*(1+(B21+(10-C21))/30),1)) -> ?
A22: =refs!A12 -> Lateral raises | B22: =refs!B12 -> 15 | C22: 8 | E22: =refs!C12 -> 14 | F22: =IF(OR(C22="?",E22<=0), "?", ROUND(E22*(1+(B22+(10-C22))/30),1)) -> 21.9 | G22: 2
A23: =refs!A12 -> Lateral raises | B23: =refs!B12 -> 15 | C23: 8 | E23: =refs!C12 -> 14 | F23: =IF(OR(C23="?",E23<=0), "?", ROUND(E23*(1+(B23+(10-C23))/30),1)) -> 21.9
A24: =refs!A12 -> Lateral raises | B24: =refs!B12 -> 15 | C24: 8 | E24: =refs!C12 -> 14 | F24: =IF(OR(C24="?",E24<=0), "?", ROUND(E24*(1+(B24+(10-C24))/30),1)) -> 21.9
A25: =refs!A12 -> Lateral raises | B25: =refs!B12 -> 15 | C25: 8 | E25: =refs!C12 -> 14 | F25: =IF(OR(C25="?",E25<=0), "?", ROUND(E25*(1+(B25+(10-C25))/30),1)) -> 21.9
A26: =refs!A13 -> Strict curl | B26: =refs!B13 -> 15 | C26: 8 | E26: =refs!C13 -> 14 | F26: =IF(OR(C26="?",E26<=0), "?", ROUND(E26*(1+(B26+(10-C26))/30),1)) -> 21.9
A27: =refs!A13 -> Strict curl | B27: =refs!B13 -> 15 | C27: 8 | E27: =refs!C13 -> 14 | F27: =IF(OR(C27="?",E27<=0), "?", ROUND(E27*(1+(B27+(10-C27))/30),1)) -> 21.9
A28: =refs!A13 -> Strict curl | B28: =refs!B13 -> 15 | C28: 8 | E28: =refs!C13 -> 14 | F28: =IF(OR(C28="?",E28<=0), "?", ROUND(E28*(1+(B28+(10-C28))/30),1)) -> 21.9
A29: =refs!A13 -> Strict curl | B29: =refs!B13 -> 15 | C29: 8 | E29: =refs!C13 -> 14 | F29: =IF(OR(C29="?",E29<=0), "?", ROUND(E29*(1+(B29+(10-C29))/30),1)) -> 21.9
A31: WEEK 3 DAY 2
A32: Exercice | B32: Reps | C32: RPE | D32: Percentage | E32: Load | F32: e1RM | G32: Part
A33: Squat | B33: 3 | C33: 5 | D33: 79 | E33: =D33/100*refs!B3 -> 94.8 | F33: =IF(OR(C33="?",E33<=0), "?", ROUND(E33*(1+(B33+(10-C33))/30),1)) -> 120.1 | G33: 1
A34: Squat | B34: 3 | C34: 7 | D34: 84 | E34: =D34/100*refs!B3 -> 100.8 | F34: =IF(OR(C34="?",E34<=0), "?", ROUND(E34*(1+(B34+(10-C34))/30),1)) -> 121
A35: Squat | B35: 3 | C35: 9 | D35: 90 | E35: =D35/100*refs!B3 -> 108 | F35: =IF(OR(C35="?",E35<=0), "?", ROUND(E35*(1+(B35+(10-C35))/30),1)) -> 122.4
A36: Tempo squat 3:1:3 | B36: 5 | C36: 7 | D36: 77 | E36: =D36/100*refs!B3 -> 92.4 | F36: =IF(OR(C36="?",E36<=0), "?", ROUND(E36*(1+(B36+(10-C36))/30),1)) -> 117
A37: Tempo squat 3:1:3 | B37: 5 | C37: 7 | D37: 77 | E37: =D37/100*refs!B3 -> 92.4 | F37: =IF(OR(C37="?",E37<=0), "?", ROUND(E37*(1+(B37+(10-C37))/30),1)) -> 117
A38: Tempo squat 3:1:3 | B38: 5 | C38: 7 | D38: 77 | E38: =D38/100*refs!B3 -> 92.4 | F38: =IF(OR(C38="?",E38<=0), "?", ROUND(E38*(1+(B38+(10-C38))/30),1)) -> 117
A39: Bench | B39: 7 | C39: 6 | D39: 71 | E39: =D39/100*refs!B4 -> 67.45 | F39: =IF(OR(C39="?",E39<=0), "?", ROUND(E39*(1+(B39+(10-C39))/30),1)) -> 92.2
A40: Bench | B40: 7 | C40: 8 | D40: 77 | E40: =D40/100*refs!B4 -> 73.15 | F40: =IF(OR(C40="?",E40<=0), "?", ROUND(E40*(1+(B40+(10-C40))/30),1)) -> 95.1
A41: Bench | B41: 7 | C41: ? | D41: 71 | E41: =D41/100*refs!B4 -> 67.45 | F41: =IF(OR(C41="?",E41<=0), "?", ROUND(E41*(1+(B41+(10-C41))/30),1)) -> ?
...

Sheet week 4
A1: WEEK 4 DAY 1
A2: Exercice | B2: Reps | C2: RPE | D2: Percentage | E2: Load | G2: Part
A3: 2CT Paused Bench | B3: 3 | C3: 6 | D3: 82 | E3: =D3/100*refs!B4 -> 77.9 | F3: =IF(OR(C3="?",E3<=0), "?", ROUND(E3*(1+(B3+(10-C3))/30),1)) -> 96.1
A4: 2CT Paused Bench | B4: 3 | C4: 8 | D4: 87 | E4: =D4/100*refs!B4 -> 82.65 | F4: =IF(OR(C4="?",E4<=0), "?", ROUND(E4*(1+(B4+(10-C4))/30),1)) -> 96.4
A5: 2CT Paused Bench | B5: 3 | C5: ? | D5: 79 | E5: =D5/100*refs!B4 -> 75.05 | F5: =IF(OR(C5="?",E5<=0), "?", ROUND(E5*(1+(B5+(10-C5))/30),1)) -> ?
A6: 2CT Paused Bench | B6: 3 | C6: ? | D6: 75 | E6: =D6/100*refs!B4 -> 71.25 | F6: =IF(OR(C6="?",E6<=0), "?", ROUND(E6*(1+(B6+(10-C6))/30),1)) -> ?
A7: 2CT Paused Bench | B7: 3 | C7: ? | D7: 75 | E7: =D7/100*refs!B4 -> 71.25 | F7: =IF(OR(C7="?",E7<=0), "?", ROUND(E7*(1+(B7+(10-C7))/30),1)) -> ?
A8: Deadlift | B8: 3 | C8: 5 | D8: 79 | E8: =D8/100*refs!B5 -> 177.75 | F8: =IF(OR(C8="?",E8<=0), "?", ROUND(E8*(1+(B8+(10-C8))/30),1)) -> 225.2
A9: Deadlift | B9: 3 | C9: 7 | D9: 85 | E9: =D9/100*refs!B5 -> 191.25 | F9: =IF(OR(C9="?",E9<=0), "?", ROUND(E9*(1+(B9+(10-C9))/30),1)) -> 229.5
A10: Deadlift | B10: 3 | C10: 5 | D10: 79 | E10: =D10/100*refs!B5 -> 177.75 | F10: =IF(OR(C10="?",E10<=0), "?", ROUND(E10*(1+(B10+(10-C10))/30),1)) -> 225.2
A11: Paused deadlift | B11: 3 | C11: 6 | D11: 75 | E11: =D11/100*refs!B5 -> 168.75 | F11: =IF(OR(C11="?",E11<=0), "?", ROUND(E11*(1+(B11+(10-C11))/30),1)) -> 208.1
A12: Paused deadlift | B12: 3 | C12: 6 | D12: 75 | E12: =D12/100*refs!B5 -> 168.75 | F12: =IF(OR(C12="?",E12<=0), "?", ROUND(E12*(1+(B12+(10-C12))/30),1)) -> 208.1
A13: =refs!A10 -> Pull-ups | B13: =refs!B10 -> 5 | C13: 8 | E13: =refs!C10 -> 0 | F13: =IF(OR(C13="?",E13<=0), "?", ROUND(E13*(1+(B13+(10-C13))/30),1)) -> ?
A14: =refs!A10 -> Pull-ups | B14: =refs!B10 -> 5 | C14: 8 | E14: =refs!C10 -> 0 | F14: =IF(OR(C14="?",E14<=0), "?", ROUND(E14*(1+(B14+(10-C14))/30),1)) -> ?
A15: =refs!A10 -> Pull-ups | B15: =refs!B10 -> 5 | C15: 8 | E15: =refs!C10 -> 0 | F15: =IF(OR(C15="?",E15<=0), "?", ROUND(E15*(1+(B15+(10-C15))/30),1)) -> ?
A16: =refs!A10 -> Pull-ups | B16: =refs!B10 -> 5 | C16: 8 | E16: =refs!C10 -> 0 | F16: =IF(OR(C16="?",E16<=0), "?", ROUND(E16*(1+(B16+(10-C16))/30),1)) -> ?
A17: =refs!A11 -> Dips | B17: =refs!B11 -> 8 | C17: 8 | E17: =refs!C11 -> 0 | F17: =IF(OR(C17="?",E17<=0), "?", ROUND(E17*(1+(B17+(10-C17))/30),1)) -> ?
A18: =refs!A11 -> Dips | B18: =refs!B11 -> 8 | C18: 8 | E18: =refs!C11 -> 0 | F18: =IF(OR(C18="?",E18<=0), "?", ROUND(E18*(1+(B18+(10-C18))/30),1)) -> ?
A19: =refs!A11 -> Dips | B19: =refs!B11 -> 8 | C19: 8 | E19: =refs!C11 -> 0 | F19: =IF(OR(C19="?",E19<=0), "?", ROUND(E19*(1+(B19+(10-C19))/30),1)) -> ?
A20: =refs!A11 -> Dips | B20: =refs!B11 -> 8 | C20: 8 | E20: =refs!C11 -> 0 | F20: =IF(OR(C20="?",E20<=0), "?", ROUND(E20*(1+(B20+(10-C20))/30),1)) -> ?
A21: =refs!A12 -> Lateral raises | B21: =refs!B12 -> 15 | C21: 8 | E21: =refs!C12 -> 14 | F21: =IF(OR(C21="?",E21<=0), "?", ROUND(E21*(1+(B21+(10-C21))/30),1)) -> 21.9 | G21: 2
A22: =refs!A12 -> Lateral raises | B22: =refs!B12 -> 15 | C22: 8 | E22: =refs!C12 -> 14 | F22: =IF(OR(C22="?",E22<=0), "?", ROUND(E22*(1+(B22+(10-C22))/30),1)) -> 21.9
A23: =refs!A12 -> Lateral raises | B23: =refs!B12 -> 15 | C23: 8 | E23: =refs!C12 -> 14 | F23: =IF(OR(C23="?",E23<=0), "?", ROUND(E23*(1+(B23+(10-C23))/30),1)) -> 21.9
A24: =refs!A12 -> Lateral raises | B24: =refs!B12 -> 15 | C24: 8 | E24: =refs!C12 -> 14 | F24: =IF(OR(C24="?",E24<=0), "?", ROUND(E24*(1+(B24+(10-C24))/30),1)) -> 21.9
A25: =refs!A13 -> Strict curl | B25: =refs!B13 -> 15 | C25: 8 | E25: =refs!C13 -> 14 | F25: =IF(OR(C25="?",E25<=0), "?", ROUND(E25*(1+(B25+(10-C25))/30),1)) -> 21.9
A26: =refs!A13 -> Strict curl | B26: =refs!B13 -> 15 | C26: 8 | E26: =refs!C13 -> 14 | F26: =IF(OR(C26="?",E26<=0), "?", ROUND(E26*(1+(B26+(10-C26))/30),1)) -> 21.9
A27: =refs!A13 -> Strict curl | B27: =refs!B13 -> 15 | C27: 8 | E27: =refs!C13 -> 14 | F27: =IF(OR(C27="?",E27<=0), "?", ROUND(E27*(1+(B27+(10-C27))/30),1)) -> 21.9
A28: =refs!A13 -> Strict curl | B28: =refs!B13 -> 15 | C28: 8 | E28: =refs!C13 -> 14 | F28: =IF(OR(C28="?",E28<=0), "?", ROUND(E28*(1+(B28+(10-C28))/30),1)) -> 21.9
A30: =refs!B14 -> 8
A31: Exercice | B31: Reps | C31: RPE | D31: Percentage | E31: Load | F31: e1RM | G31: Part
A32: Squat | B32: 3 | C32: 5 | D32: 79 | E32: =D32/100*refs!B3 -> 94.8 | F32: =IF(OR(C32="?",E32<=0), "?", ROUND(E32*(1+(B32+(10-C32))/30),1)) -> 120.1 | G32: 1
A33: Squat | B33: 3 | C33: 7 | D33: 84 | E33: =D33/100*refs!B3 -> 100.8 | F33: =IF(OR(C33="?",E33<=0), "?", ROUND(E33*(1+(B33+(10-C33))/30),1)) -> 121
A34: Squat | B34: 3 | C34: 5 | D34: 79 | E34: =D34/100*refs!B3 -> 94.8 | F34: =IF(OR(C34="?",E34<=0), "?", ROUND(E34*(1+(B34+(10-C34))/30),1)) -> 120.1
A35: Tempo squat 3:1:3 | B35: 5 | C35: 7 | D35: 77 | E35: =D35/100*refs!B3 -> 92.4 | F35: =IF(OR(C35="?",E35<=0), "?", ROUND(E35*(1+(B35+(10-C35))/30),1)) -> 117
A36: Tempo squat 3:1:3 | B36: 5 | C36: 7 | D36: 77 | E36: =D36/100*refs!B3 -> 92.4 | F36: =IF(OR(C36="?",E36<=0), "?", ROUND(E36*(1+(B36+(10-C36))/30),1)) -> 117
A37: Bench | B37: 7 | C37: 6 | D37: 71 | E37: =D37/100*refs!B4 -> 67.45 | F37: =IF(OR(C37="?",E37<=0), "?", ROUND(E37*(1+(B37+(10-C37))/30),1)) -> 92.2
A38: Bench | B38: 7 | C38: 8 | D38: 77 | E38: =D38/100*refs!B4 -> 73.15 | F38: =IF(OR(C38="?",E38<=0), "?", ROUND(E38*(1+(B38+(10-C38))/30),1)) -> 95.1
A39: Bench | B39: 7 | C39: ? | D39: 71 | E39: =D39/100*refs!B4 -> 67.45 | F39: =IF(OR(C39="?",E39<=0), "?", ROUND(E39*(1+(B39+(10-C39))/30),1)) -> ?
A40: Bench | B40: 7 | C40: ? | D40: 66 | E40: =D40/100*refs!B4 -> 62.7 | F40: =IF(OR(C40="?",E40<=0), "?", ROUND(E40*(1+(B40+(10-C40))/30),1)) -> ?
A41: =refs!A14 -> Dumbbel rowing | B41: =refs!B14 -> 8 | C41: 8 | E41: =refs!C14 -> 46 | F41: =IF(OR(C41="?",E41<=0), "?", ROUND(E41*(1+(B41+(10-C41))/30),1)) -> 61.3
...

Sheet week 5
A1: WEEK 5 DAY 1
A2: Exercice | B2: Reps | C2: RPE | D2: Percentage | E2: Load | F2: e1RM | G2: Part
A3: 2CT Paused Bench | B3: 6 | C3: 5 | D3: 71 | E3: =D3/100*refs!B4 -> 67.45 | F3: =IF(OR(C3="?",E3<=0), "?", ROUND(E3*(1+(B3+(10-C3))/30),1)) -> 92.2
A4: 2CT Paused Bench | B4: 6 | C4: 7 | D4: 76 | E4: =D4/100*refs!B4 -> 72.2 | F4: =IF(OR(C4="?",E4<=0), "?", ROUND(E4*(1+(B4+(10-C4))/30),1)) -> 93.9
A5: 2CT Paused Bench | B5: 6 | C5: 7 | D5: 76 | E5: =D5/100*refs!B4 -> 72.2 | F5: =IF(OR(C5="?",E5<=0), "?", ROUND(E5*(1+(B5+(10-C5))/30),1)) -> 93.9
A6: 2CT Paused Bench | B6: 6 | C6: 7 | D6: 76 | E6: =D6/100*refs!B4 -> 72.2 | F6: =IF(OR(C6="?",E6<=0), "?", ROUND(E6*(1+(B6+(10-C6))/30),1)) -> 93.9
A7: Deadlift | B7: 2 | C7: 5 | D7: 81 | E7: =D7/100*refs!B5 -> 182.25 | F7: =IF(OR(C7="?",E7<=0), "?", ROUND(E7*(1+(B7+(10-C7))/30),1)) -> 224.8
A8: Deadlift | B8: 2 | C8: 7 | D8: 86 | E8: =D8/100*refs!B5 -> 193.5 | F8: =IF(OR(C8="?",E8<=0), "?", ROUND(E8*(1+(B8+(10-C8))/30),1)) -> 225.8
A9: Deadlift | B9: 2 | C9: ? | D9: 82 | E9: =D9/100*refs!B5 -> 184.5 | F9: =IF(OR(C9="?",E9<=0), "?", ROUND(E9*(1+(B9+(10-C9))/30),1)) -> ?
A10: =refs!A10 -> Pull-ups | B10: =refs!B10 -> 5 | C10: 8 | E10: =refs!C10 -> 0 | F10: =IF(OR(C10="?",E10<=0), "?", ROUND(E10*(1+(B10+(10-C10))/30),1)) -> ?
A11: =refs!A10 -> Pull-ups | B11: =refs!B10 -> 5 | C11: 8 | E11: =refs!C10 -> 0 | F11: =IF(OR(C11="?",E11<=0), "?", ROUND(E11*(1+(B11+(10-C11))/30),1)) -> ?
A12: =refs!A10 -> Pull-ups | B12: =refs!B10 -> 5 | C12: 8 | E12: =refs!C10 -> 0 | F12: =IF(OR(C12="?",E12<=0), "?", ROUND(E12*(1+(B12+(10-C12))/30),1)) -> ?
A13: =refs!A10 -> Pull-ups | B13: =refs!B10 -> 5 | C13: 8 | E13: =refs!C10 -> 0 | F13: =IF(OR(C13="?",E13<=0), "?", ROUND(E13*(1+(B13+(10-C13))/30),1)) -> ?
A14: =refs!A11 -> Dips | B14: =refs!B11 -> 8 | C14: 8 | E14: =refs!C11 -> 0 | F14: =IF(OR(C14="?",E14<=0), "?", ROUND(E14*(1+(B14+(10-C14))/30),1)) -> ?
A15: =refs!A11 -> Dips | B15: =refs!B11 -> 8 | C15: 8 | E15: =refs!C11 -> 0 | F15: =IF(OR(C15="?",E15<=0), "?", ROUND(E15*(1+(B15+(10-C15))/30),1)) -> ?
A16: =refs!A11 -> Dips | B16: =refs!B11 -> 8 | C16: 8 | E16: =refs!C11 -> 0 | F16: =IF(OR(C16="?",E16<=0), "?", ROUND(E16*(1+(B16+(10-C16))/30),1)) -> ?
A17: =refs!A11 -> Dips | B17: =refs!B11 -> 8 | C17: 8 | E17: =refs!C11 -> 0 | F17: =IF(OR(C17="?",E17<=0), "?", ROUND(E17*(1+(B17+(10-C17))/30),1)) -> ?
A18: =refs!A12 -> Lateral raises | B18: =refs!B12 -> 15 | C18: 8 | E18: =refs!C12 -> 14 | F18: =IF(OR(C18="?",E18<=0), "?", ROUND(E18*(1+(B18+(10-C18))/30),1)) -> 21.9 | G18: 2
A19: =refs!A12 -> Lateral raises | B19: =refs!B12 -> 15 | C19: 8 | E19: =refs!C12 -> 14 | F19: =IF(OR(C19="?",E19<=0), "?", ROUND(E19*(1+(B19+(10-C19))/30),1)) -> 21.9
A20: =refs!A12 -> Lateral raises | B20: =refs!B12 -> 15 | C20: 8 | E20: =refs!C12 -> 14 | F20: =IF(OR(C20="?",E20<=0), "?", ROUND(E20*(1+(B20+(10-C20))/30),1)) -> 21.9
A21: =refs!A12 -> Lateral raises | B21: =refs!B12 -> 15 | C21: 8 | E21: =refs!C12 -> 14 | F21: =IF(OR(C21="?",E21<=0), "?", ROUND(E21*(1+(B21+(10-C21))/30),1)) -> 21.9
A22: =refs!A13 -> Strict curl | B22: =refs!B13 -> 15 | C22: 8 | E22: =refs!C13 -> 14 | F22: =IF(OR(C22="?",E22<=0), "?", ROUND(E22*(1+(B22+(10-C22))/30),1)) -> 21.9
A23: =refs!A13 -> Strict curl | B23: =refs!B13 -> 15 | C23: 8 | E23: =refs!C13 -> 14 | F23: =IF(OR(C23="?",E23<=0), "?", ROUND(E23*(1+(B23+(10-C23))/30),1)) -> 21.9
A24: =refs!A13 -> Strict curl | B24: =refs!B13 -> 15 | C24: 8 | E24: =refs!C13 -> 14 | F24: =IF(OR(C24="?",E24<=0), "?", ROUND(E24*(1+(B24+(10-C24))/30),1)) -> 21.9
A25: =refs!A13 -> Strict curl | B25: =refs!B13 -> 15 | C25: 8 | E25: =refs!C13 -> 14 | F25: =IF(OR(C25="?",E25<=0), "?", ROUND(E25*(1+(B25+(10-C25))/30),1)) -> 21.9
A27: WEEK 5 DAY 2
A28: Exercice | B28: Reps | C28: RPE | D28: Percentage | E28: Load | F28: e1RM | G28: Part
A29: Squat | B29: 6 | C29: 5 | D29: 71 | E29: =D29/100*refs!B3 -> 85.2 | F29: =IF(OR(C29="?",E29<=0), "?", ROUND(E29*(1+(B29+(10-C29))/30),1)) -> 116.4 | G29: 1
A30: Squat | B30: 6 | C30: 6 | D30: 74 | E30: =D30/100*refs!B3 -> 88.8 | F30: =IF(OR(C30="?",E30<=0), "?", ROUND(E30*(1+(B30+(10-C30))/30),1)) -> 118.4
A31: Squat | B31: 6 | C31: 6 | D31: 74 | E31: =D31/100*refs!B3 -> 88.8 | F31: =IF(OR(C31="?",E31<=0), "?", ROUND(E31*(1+(B31+(10-C31))/30),1)) -> 118.4
A32: Reverse bar squat | B32: 8 | C32: 5 | D32: 65 | E32: =D32/100*refs!B3 -> 78 | F32: =IF(OR(C32="?",E32<=0), "?", ROUND(E32*(1+(B32+(10-C32))/30),1)) -> 111.8
A33: Reverse bar squat | B33: 8 | C33: 7 | D33: 71 | E33: =D33/100*refs!B3 -> 85.2 | F33: =IF(OR(C33="?",E33<=0), "?", ROUND(E33*(1+(B33+(10-C33))/30),1)) -> 116.4
A34: Reverse bar squat | B34: 8 | C34: 7 | D34: 71 | E34: =D34/100*refs!B3 -> 85.2 | F34: =IF(OR(C34="?",E34<=0), "?", ROUND(E34*(1+(B34+(10-C34))/30),1)) -> 116.4
A35: Bench | B35: 10 | C35: 8 | D35: 69 | E35: =D35/100*refs!B4 -> 65.55 | F35: =IF(OR(C35="?",E35<=0), "?", ROUND(E35*(1+(B35+(10-C35))/30),1)) -> 91.8
A36: Bench | B36: 10 | C36: ? | D36: 61 | E36: =D36/100*refs!B4 -> 57.95 | F36: =IF(OR(C36="?",E36<=0), "?", ROUND(E36*(1+(B36+(10-C36))/30),1)) -> ?
A37: Bench | B37: 10 | C37: ? | D37: 61 | E37: =D37/100*refs!B4 -> 57.95 | F37: =IF(OR(C37="?",E37<=0), "?", ROUND(E37*(1+(B37+(10-C37))/30),1)) -> ?
A38: =refs!A14 -> Dumbbel rowing | B38: =refs!B14 -> 8 | C38: 8 | E38: =refs!C14 -> 46 | F38: =IF(OR(C38="?",E38<=0), "?", ROUND(E38*(1+(B38+(10-C38))/30),1)) -> 61.3
A39: =refs!A14 -> Dumbbel rowing | B39: =refs!B14 -> 8 | C39: 8 | E39: =refs!C14 -> 46 | F39: =IF(OR(C39="?",E39<=0), "?", ROUND(E39*(1+(B39+(10-C39))/30),1)) -> 61.3
A40: =refs!A14 -> Dumbbel rowing | B40: =refs!B14 -> 8 | C40: 8 | E40: =refs!C14 -> 46 | F40: =IF(OR(C40="?",E40<=0), "?", ROUND(E40*(1+(B40+(10-C40))/30),1)) -> 61.3
A41: =refs!A14 -> Dumbbel rowing | B41: =refs!B14 -> 8 | C41: 8 | E41: =refs!C14 -> 46 | F41: =IF(OR(C41="?",E41<=0), "?", ROUND(E41*(1+(B41+(10-C41))/30),1)) -> 61.3
...
